<?xml version="1.0" encoding="utf-8"?>
<!-- This URDF was automatically created by SolidWorks to URDF Exporter! Originally created by Stephen Brawner (brawner@gmail.com) 
     Commit Version: 1.6.0-1-g15f4949  Build Version: 1.6.7594.29634
     For more information, please see http://wiki.ros.org/sw_urdf_exporter -->
<robot
  name="spidey">
  <link
    name="base_link">
    <inertial>
      <origin
        xyz="4.17901123495948E-05 -0.000193636356481966 0.0894913595711994"
        rpy="0 0 0" />
      <mass
        value="0.117924372960691" />
      <inertia
        ixx="0.000102932488829953"
        ixy="-9.63420593853609E-07"
        ixz="-2.02132312411461E-09"
        iyy="8.92346469386853E-05"
        iyz="4.58614714148341E-11"
        izz="0.000185817181019725" />
    </inertial>
    <visual>
      <origin
        xyz="0 0 0"
        rpy="0 0 0" />
      <geometry>
        <mesh
          filename="base_link.obj" />
      </geometry>
      <material
        name="">
        <color
          rgba="0.250980392156863 0.250980392156863 0.250980392156863 1" />
      </material>
    </visual>
    <collision>
      <origin
        xyz="0 0 0"
        rpy="0 0 0" />
      <geometry>
        <mesh
          filename="base_link.obj" />
      </geometry>
    </collision>
  </link>
  <link
    name="leg1_link1">
    <inertial>
      <origin
        xyz="-0.022108937837177 -0.0132421365474836 0.00314002313535409"
        rpy="0 0 0" />
      <mass
        value="0.00723872418872688" />
      <inertia
        ixx="5.22774747679676E-07"
        ixy="-1.49834845338892E-07"
        ixz="3.6805593515317E-07"
        iyy="3.27257999855942E-06"
        iyz="2.85909361784707E-08"
        izz="3.21653958635831E-06" />
    </inertial>
    <visual>
      <origin
        xyz="0 0 0"
        rpy="0 0 0" />
      <geometry>
        <mesh
          filename="leg1_link1.obj" />
      </geometry>
      <material
        name="">
        <color
          rgba="0.752941176470588 0 0 1" />
      </material>
    </visual>
    <collision>
      <origin
        xyz="0 0 0"
        rpy="0 0 0" />
      <geometry>
        <mesh
          filename="leg1_link1.obj" />
      </geometry>
    </collision>
  </link>
  <joint
    name="leg1_joint1"
    type="revolute">
    <origin
      xyz="0.046464 -0.046464 0.0821"
      rpy="-1.5708 0 2.3562" />
    <parent
      link="base_link" />
    <child
      link="leg1_link1" />
    <axis
      xyz="0 1 0" />
    <limit
      lower="-1.74533"
      upper="1.39626"
      effort="15"
      velocity="7" />
  </joint>
  <link
    name="leg1_link2">
    <inertial>
      <origin
        xyz="0.0355 -6.93889390390723E-18 -0.00424439919105857"
        rpy="0 0 0" />
      <mass
        value="0.0122900929113511" />
      <inertia
        ixx="3.89424770122985E-06"
        ixy="4.38413027053517E-22"
        ixz="1.48230765769503E-21"
        iyy="8.48053814353777E-06"
        iyz="7.0606481389755E-22"
        izz="5.00726458223547E-06" />
    </inertial>
    <visual>
      <origin
        xyz="0 0 0"
        rpy="0 0 0" />
      <geometry>
        <mesh
          filename="leg1_link2.obj" />
      </geometry>
      <material
        name="">
        <color
          rgba="0.250980392156863 0.250980392156863 0.250980392156863 1" />
      </material>
    </visual>
    <collision>
      <origin
        xyz="0 0 0"
        rpy="0 0 0" />
      <geometry>
        <mesh
          filename="leg1_link2.obj" />
      </geometry>
    </collision>
  </link>
  <joint
    name="leg1_joint2"
    type="revolute">
    <origin
      xyz="-0.033 -0.0145 0"
      rpy="0 0 3.1416" />
    <parent
      link="leg1_link1" />
    <child
      link="leg1_link2" />
    <axis
      xyz="0 0 1" />
    <limit
      lower="-1.5708"
      upper="2.35619"
      effort="15"
      velocity="7" />
  </joint>
  <link
    name="leg1_link3">
    <inertial>
      <origin
        xyz="-0.0119414613806721 0.00574131595236861 -0.0233720198168789"
        rpy="0 0 0" />
      <mass
        value="0.0168535864832978" />
      <inertia
        ixx="9.00062618488712E-06"
        ixy="5.26664899139276E-08"
        ixz="-1.77596400601993E-06"
        iyy="9.92645327766751E-06"
        iyz="4.40450718188812E-07"
        izz="2.02787228352354E-06" />
    </inertial>
    <visual>
      <origin
        xyz="0 0 0"
        rpy="0 0 0" />
      <geometry>
        <mesh
          filename="leg1_link3.obj" />
      </geometry>
      <material
        name="">
        <color
          rgba="0.752941176470588 0 0 1" />
      </material>
    </visual>
    <collision>
      <origin
        xyz="0 0 0"
        rpy="0 0 0" />
      <geometry>
        <mesh
          filename="leg1_link3.obj" />
      </geometry>
    </collision>
  </link>
  <joint
    name="leg1_joint3"
    type="revolute">
    <origin
      xyz="0.071 0 0"
      rpy="1.5708 0 3.1416" />
    <parent
      link="leg1_link2" />
    <child
      link="leg1_link3" />
    <axis
      xyz="0 1 0" />
    <limit
      lower="-1.39626"
      upper="1.5708"
      effort="15"
      velocity="7" />
  </joint>
  <link
    name="leg1_link3_tip">
    <inertial>
      <origin
        xyz="-0.00123745228213162 5.00000000000084E-05 -0.00181663716020534"
        rpy="0 0 0" />
      <mass
        value="9.90841781413794E-07" />
      <inertia
        ixx="1.31973845371642E-12"
        ixy="9.25239285899653E-30"
        ixz="3.14914107837011E-13"
        iyy="1.93826926659808E-12"
        iyz="-6.61960872038841E-31"
        izz="6.20182215850679E-13" />
    </inertial>
    <visual>
      <origin
        xyz="0 0 0"
        rpy="0 0 0" />
      <geometry>
        <mesh
          filename="leg1_link3_tip.obj" />
      </geometry>
      <material
        name="">
        <color
          rgba="0.752941176470588 0 0 1" />
      </material>
    </visual>
    <collision>
      <origin
        xyz="0 0 0"
        rpy="0 0 0" />
      <geometry>
        <mesh
          filename="leg1_link3_tip.obj" />
      </geometry>
    </collision>
  </link>
  <joint
    name="leg1_joint3_tip"
    type="fixed">
    <origin
      xyz="-0.019 0.0095 -0.0966"
      rpy="1.5708 0 0" />
    <parent
      link="leg1_link3" />
    <child
      link="leg1_link3_tip" />
    <axis
      xyz="0 0 0" />
  </joint>
  <link
    name="leg2_link1">
    <inertial>
      <origin
        xyz="-0.022108937837177 -0.0132421365474836 0.00314002313535408"
        rpy="0 0 0" />
      <mass
        value="0.00723872418872687" />
      <inertia
        ixx="5.22774747679675E-07"
        ixy="-1.49834845338892E-07"
        ixz="3.6805593515317E-07"
        iyy="3.27257999855941E-06"
        iyz="2.85909361784708E-08"
        izz="3.2165395863583E-06" />
    </inertial>
    <visual>
      <origin
        xyz="0 0 0"
        rpy="0 0 0" />
      <geometry>
        <mesh
          filename="leg2_link1.obj" />
      </geometry>
      <material
        name="">
        <color
          rgba="0.752941176470588 0 0 1" />
      </material>
    </visual>
    <collision>
      <origin
        xyz="0 0 0"
        rpy="0 0 0" />
      <geometry>
        <mesh
          filename="leg2_link1.obj" />
      </geometry>
    </collision>
  </link>
  <joint
    name="leg2_joint1"
    type="revolute">
    <origin
      xyz="0.046464 0.046464 0.0821"
      rpy="-1.5708 0 -2.3562" />
    <parent
      link="base_link" />
    <child
      link="leg2_link1" />
    <axis
      xyz="0 1 0" />
    <limit
      lower="-1.74533"
      upper="1.39626"
      effort="15"
      velocity="7" />
  </joint>
  <link
    name="leg2_link2">
    <inertial>
      <origin
        xyz="0.0355 0 -0.0042443991910585"
        rpy="0 0 0" />
      <mass
        value="0.0122900929113511" />
      <inertia
        ixx="3.89424770122985E-06"
        ixy="1.23757276075668E-21"
        ixz="2.11758236813575E-21"
        iyy="8.48053814353775E-06"
        iyz="2.66262005200978E-22"
        izz="5.00726458223546E-06" />
    </inertial>
    <visual>
      <origin
        xyz="0 0 0"
        rpy="0 0 0" />
      <geometry>
        <mesh
          filename="leg2_link2.obj" />
      </geometry>
      <material
        name="">
        <color
          rgba="0.250980392156863 0.250980392156863 0.250980392156863 1" />
      </material>
    </visual>
    <collision>
      <origin
        xyz="0 0 0"
        rpy="0 0 0" />
      <geometry>
        <mesh
          filename="leg2_link2.obj" />
      </geometry>
    </collision>
  </link>
  <joint
    name="leg2_joint2"
    type="revolute">
    <origin
      xyz="-0.033 -0.0145 0"
      rpy="0 0 3.1416" />
    <parent
      link="leg2_link1" />
    <child
      link="leg2_link2" />
    <axis
      xyz="0 0 1" />
    <limit
      lower="-1.5708"
      upper="2.35619"
      effort="15"
      velocity="7" />
  </joint>
  <link
    name="leg2_link3">
    <inertial>
      <origin
        xyz="-0.0119414613806721 0.00574131595236858 -0.023372019816879"
        rpy="0 0 0" />
      <mass
        value="0.0168535864832979" />
      <inertia
        ixx="9.0006261848872E-06"
        ixy="5.2666489913928E-08"
        ixz="-1.77596400601994E-06"
        iyy="9.92645327766759E-06"
        iyz="4.40450718188823E-07"
        izz="2.02787228352354E-06" />
    </inertial>
    <visual>
      <origin
        xyz="0 0 0"
        rpy="0 0 0" />
      <geometry>
        <mesh
          filename="leg2_link3.obj" />
      </geometry>
      <material
        name="">
        <color
          rgba="0.752941176470588 0 0 1" />
      </material>
    </visual>
    <collision>
      <origin
        xyz="0 0 0"
        rpy="0 0 0" />
      <geometry>
        <mesh
          filename="leg2_link3.obj" />
      </geometry>
    </collision>
  </link>
  <joint
    name="leg2_joint3"
    type="revolute">
    <origin
      xyz="0.071 0 0"
      rpy="1.5708 0 3.1416" />
    <parent
      link="leg2_link2" />
    <child
      link="leg2_link3" />
    <axis
      xyz="0 1 0" />
    <limit
      lower="-1.39626"
      upper="1.5708"
      effort="15"
      velocity="7" />
  </joint>
  <link
    name="leg2_link3_tip">
    <inertial>
      <origin
        xyz="-0.00123745228213168 4.99999999999945E-05 -0.00181663716020532"
        rpy="0 0 0" />
      <mass
        value="9.90841781413787E-07" />
      <inertia
        ixx="1.31973845371641E-12"
        ixy="6.36413057061503E-29"
        ixz="3.14914107837001E-13"
        iyy="1.93826926659805E-12"
        iyz="-9.86813689522352E-29"
        izz="6.20182215850666E-13" />
    </inertial>
    <visual>
      <origin
        xyz="0 0 0"
        rpy="0 0 0" />
      <geometry>
        <mesh
          filename="leg2_link3_tip.obj" />
      </geometry>
      <material
        name="">
        <color
          rgba="0.752941176470588 0 0 1" />
      </material>
    </visual>
    <collision>
      <origin
        xyz="0 0 0"
        rpy="0 0 0" />
      <geometry>
        <mesh
          filename="leg2_link3_tip.obj" />
      </geometry>
    </collision>
  </link>
  <joint
    name="leg2_joint3_tip"
    type="fixed">
    <origin
      xyz="-0.019 0.0095 -0.0966"
      rpy="1.5708 0 0" />
    <parent
      link="leg2_link3" />
    <child
      link="leg2_link3_tip" />
    <axis
      xyz="0 0 0" />
  </joint>
  <link
    name="leg3_link1">
    <inertial>
      <origin
        xyz="-0.022108937837177 -0.0132421365474836 0.00314002313535407"
        rpy="0 0 0" />
      <mass
        value="0.00723872418872689" />
      <inertia
        ixx="5.22774747679675E-07"
        ixy="-1.49834845338892E-07"
        ixz="3.68055935153169E-07"
        iyy="3.27257999855942E-06"
        iyz="2.85909361784709E-08"
        izz="3.2165395863583E-06" />
    </inertial>
    <visual>
      <origin
        xyz="0 0 0"
        rpy="0 0 0" />
      <geometry>
        <mesh
          filename="leg3_link1.obj" />
      </geometry>
      <material
        name="">
        <color
          rgba="0.752941176470588 0 0 1" />
      </material>
    </visual>
    <collision>
      <origin
        xyz="0 0 0"
        rpy="0 0 0" />
      <geometry>
        <mesh
          filename="leg3_link1.obj" />
      </geometry>
    </collision>
  </link>
  <joint
    name="leg3_joint1"
    type="revolute">
    <origin
      xyz="-0.046464 -0.046464 0.0821"
      rpy="-1.5708 0 0.7854" />
    <parent
      link="base_link" />
    <child
      link="leg3_link1" />
    <axis
      xyz="0 1 0" />
    <limit
      lower="-1.74533"
      upper="1.39626"
      effort="15"
      velocity="7" />
  </joint>
  <link
    name="leg3_link2">
    <inertial>
      <origin
        xyz="0.0355 0 -0.00424439919105854"
        rpy="0 0 0" />
      <mass
        value="0.0122900929113511" />
      <inertia
        ixx="3.89424770122985E-06"
        ixy="-5.43649474491498E-22"
        ixz="-6.35274710440725E-21"
        iyy="8.48053814353775E-06"
        iyz="-1.34889793614773E-22"
        izz="5.00726458223546E-06" />
    </inertial>
    <visual>
      <origin
        xyz="0 0 0"
        rpy="0 0 0" />
      <geometry>
        <mesh
          filename="leg3_link2.obj" />
      </geometry>
      <material
        name="">
        <color
          rgba="0.250980392156863 0.250980392156863 0.250980392156863 1" />
      </material>
    </visual>
    <collision>
      <origin
        xyz="0 0 0"
        rpy="0 0 0" />
      <geometry>
        <mesh
          filename="leg3_link2.obj" />
      </geometry>
    </collision>
  </link>
  <joint
    name="leg3_joint2"
    type="revolute">
    <origin
      xyz="-0.033 -0.0145 0"
      rpy="0 0 3.1416" />
    <parent
      link="leg3_link1" />
    <child
      link="leg3_link2" />
    <axis
      xyz="0 0 1" />
    <limit
      lower="-1.5708"
      upper="2.35619"
      effort="15"
      velocity="7" />
  </joint>
  <link
    name="leg3_link3">
    <inertial>
      <origin
        xyz="-0.0119414613806721 0.00574131595236865 -0.023372019816879"
        rpy="0 0 0" />
      <mass
        value="0.0168535864832979" />
      <inertia
        ixx="9.00062618488723E-06"
        ixy="5.26664899139306E-08"
        ixz="-1.77596400601993E-06"
        iyy="9.92645327766761E-06"
        iyz="4.40450718188821E-07"
        izz="2.02787228352354E-06" />
    </inertial>
    <visual>
      <origin
        xyz="0 0 0"
        rpy="0 0 0" />
      <geometry>
        <mesh
          filename="leg3_link3.obj" />
      </geometry>
      <material
        name="">
        <color
          rgba="0.752941176470588 0 0 1" />
      </material>
    </visual>
    <collision>
      <origin
        xyz="0 0 0"
        rpy="0 0 0" />
      <geometry>
        <mesh
          filename="leg3_link3.obj" />
      </geometry>
    </collision>
  </link>
  <joint
    name="leg3_joint3"
    type="revolute">
    <origin
      xyz="0.071 0 0"
      rpy="1.5708 0 3.1416" />
    <parent
      link="leg3_link2" />
    <child
      link="leg3_link3" />
    <axis
      xyz="0 1 0" />
    <limit
      lower="-1.39626"
      upper="1.5708"
      effort="15"
      velocity="7" />
  </joint>
  <link
    name="leg3_link3_tip">
    <inertial>
      <origin
        xyz="-0.00123745228213162 5.00000000000014E-05 -0.00181663716020536"
        rpy="0 0 0" />
      <mass
        value="9.9084178141379E-07" />
      <inertia
        ixx="1.31973845371641E-12"
        ixy="3.09429100946932E-29"
        ixz="3.14914107837003E-13"
        iyy="1.93826926659806E-12"
        iyz="-2.88941907834146E-29"
        izz="6.20182215850672E-13" />
    </inertial>
    <visual>
      <origin
        xyz="0 0 0"
        rpy="0 0 0" />
      <geometry>
        <mesh
          filename="leg3_link3_tip.obj" />
      </geometry>
      <material
        name="">
        <color
          rgba="0.752941176470588 0 0 1" />
      </material>
    </visual>
    <collision>
      <origin
        xyz="0 0 0"
        rpy="0 0 0" />
      <geometry>
        <mesh
          filename="leg3_link3_tip.obj" />
      </geometry>
    </collision>
  </link>
  <joint
    name="leg3_joint3_tip"
    type="fixed">
    <origin
      xyz="-0.019 0.0095 -0.0966"
      rpy="1.5708 0 0" />
    <parent
      link="leg3_link3" />
    <child
      link="leg3_link3_tip" />
    <axis
      xyz="0 0 0" />
  </joint>
  <link
    name="leg4_link1">
    <inertial>
      <origin
        xyz="-0.022108937837177 -0.0132421365474836 0.00314002313535406"
        rpy="0 0 0" />
      <mass
        value="0.00723872418872688" />
      <inertia
        ixx="5.22774747679676E-07"
        ixy="-1.49834845338892E-07"
        ixz="3.68055935153169E-07"
        iyy="3.27257999855942E-06"
        iyz="2.85909361784708E-08"
        izz="3.21653958635831E-06" />
    </inertial>
    <visual>
      <origin
        xyz="0 0 0"
        rpy="0 0 0" />
      <geometry>
        <mesh
          filename="leg4_link1.obj" />
      </geometry>
      <material
        name="">
        <color
          rgba="0.752941176470588 0 0 1" />
      </material>
    </visual>
    <collision>
      <origin
        xyz="0 0 0"
        rpy="0 0 0" />
      <geometry>
        <mesh
          filename="leg4_link1.obj" />
      </geometry>
    </collision>
  </link>
  <joint
    name="leg4_joint1"
    type="revolute">
    <origin
      xyz="-0.046464 0.046464 0.0821"
      rpy="-1.5708 0 -0.7854" />
    <parent
      link="base_link" />
    <child
      link="leg4_link1" />
    <axis
      xyz="0 1 0" />
    <limit
      lower="-1.74533"
      upper="1.39626"
      effort="15"
      velocity="7" />
  </joint>
  <link
    name="leg4_link2">
    <inertial>
      <origin
        xyz="0.0355 0 -0.00424439919105854"
        rpy="0 0 0" />
      <mass
        value="0.0122900929113511" />
      <inertia
        ixx="3.89424770122986E-06"
        ixy="1.16804998458628E-23"
        ixz="4.2351647362715E-22"
        iyy="8.48053814353777E-06"
        iyz="2.78693654281205E-22"
        izz="5.00726458223547E-06" />
    </inertial>
    <visual>
      <origin
        xyz="0 0 0"
        rpy="0 0 0" />
      <geometry>
        <mesh
          filename="leg4_link2.obj" />
      </geometry>
      <material
        name="">
        <color
          rgba="0.250980392156863 0.250980392156863 0.250980392156863 1" />
      </material>
    </visual>
    <collision>
      <origin
        xyz="0 0 0"
        rpy="0 0 0" />
      <geometry>
        <mesh
          filename="leg4_link2.obj" />
      </geometry>
    </collision>
  </link>
  <joint
    name="leg4_joint2"
    type="revolute">
    <origin
      xyz="-0.033 -0.0145 0"
      rpy="0 0 3.1416" />
    <parent
      link="leg4_link1" />
    <child
      link="leg4_link2" />
    <axis
      xyz="0 0 1" />
    <limit
      lower="-1.5708"
      upper="2.35619"
      effort="15"
      velocity="7" />
  </joint>
  <link
    name="leg4_link3">
    <inertial>
      <origin
        xyz="-0.0119414613806721 0.00574131595236852 -0.023372019816879"
        rpy="0 0 0" />
      <mass
        value="0.0168535864832979" />
      <inertia
        ixx="9.00062618488721E-06"
        ixy="5.26664899139285E-08"
        ixz="-1.77596400601994E-06"
        iyy="9.92645327766759E-06"
        iyz="4.40450718188824E-07"
        izz="2.02787228352354E-06" />
    </inertial>
    <visual>
      <origin
        xyz="0 0 0"
        rpy="0 0 0" />
      <geometry>
        <mesh
          filename="leg4_link3.obj" />
      </geometry>
      <material
        name="">
        <color
          rgba="0.752941176470588 0 0 1" />
      </material>
    </visual>
    <collision>
      <origin
        xyz="0 0 0"
        rpy="0 0 0" />
      <geometry>
        <mesh
          filename="leg4_link3.obj" />
      </geometry>
    </collision>
  </link>
  <joint
    name="leg4_joint3"
    type="revolute">
    <origin
      xyz="0.071 0 0"
      rpy="1.5708 0 3.1416" />
    <parent
      link="leg4_link2" />
    <child
      link="leg4_link3" />
    <axis
      xyz="0 1 0" />
    <limit
      lower="-1.39626"
      upper="1.5708"
      effort="15"
      velocity="7" />
  </joint>
  <link
    name="leg4_link3_tip">
    <inertial>
      <origin
        xyz="-0.00123745228213169 5.00000000000014E-05 -0.00181663716020532"
        rpy="0 0 0" />
      <mass
        value="9.90841781413788E-07" />
      <inertia
        ixx="1.31973845371641E-12"
        ixy="-3.49299266851849E-30"
        ixz="3.14914107837004E-13"
        iyy="1.93826926659805E-12"
        iyz="1.32369724924107E-29"
        izz="6.20182215850664E-13" />
    </inertial>
    <visual>
      <origin
        xyz="0 0 0"
        rpy="0 0 0" />
      <geometry>
        <mesh
          filename="leg4_link3_tip.obj" />
      </geometry>
      <material
        name="">
        <color
          rgba="0.752941176470588 0 0 1" />
      </material>
    </visual>
    <collision>
      <origin
        xyz="0 0 0"
        rpy="0 0 0" />
      <geometry>
        <mesh
          filename="leg4_link3_tip.obj" />
      </geometry>
    </collision>
  </link>
  <joint
    name="leg4_joint3_tip"
    type="fixed">
    <origin
      xyz="-0.019 0.0095 -0.0966"
      rpy="1.5708 0 0" />
    <parent
      link="leg4_link3" />
    <child
      link="leg4_link3_tip" />
    <axis
      xyz="0 0 0" />
  </joint>
</robot>